<?xml version="1.0"?>
<robot name="Greyhound">
<!-- TORSO -->
  <link name="torso">
    <visual>
      <geometry>
        <box size="0.4 0.15 0.1"/>
      </geometry>
      <material name="gray">
        <color rgba="0.6 0.6 0.6 1"/>
      </material>
    </visual>
    <collision>
    <origin xyz="0 0 0"/>
    <geometry>
      <box size="0.3 0.15 0.1"/>
    </geometry>
  </collision>
<inertial>
    <origin xyz="0 0 0"/>
    <mass value="0.7"/>
    <inertia ixx="0.0001" iyy="0.0001" izz="0.0001"
             ixy="0" ixz="0" iyz="0"/>
</inertial> 
  </link>
<!-- FRONT RIGHT THIGH -->
  <link name="fr_thigh">
   <visual>
     <origin xyz="0 0 -0.075"/> 
     <geometry>
        <box size="0.05 0.05 0.15"/>
     </geometry>
     <material name="light_gray">
     <color rgba="0.7 0.7 0.7 1"/>
     </material>
   </visual>
   <collision>
    <origin xyz="0 0 -0.075"/>
    <geometry>
      <box size="0.05 0.05 0.15"/>
    </geometry>
  </collision>
<inertial>
    <origin xyz="0 0 0"/>
    <mass value="0.2"/>
    <inertia ixx="0.0001" iyy="0.0001" izz="0.0001"
             ixy="0" ixz="0" iyz="0"/>
</inertial> 
  </link>
<!--FRONT RIGHT SHIN -->
  <link name="fr_shin"> 
    <visual>
     <origin xyz="0 0 -0.15"/>
    <geometry>
      <box size="0.03 0.05 0.15"/>
    </geometry>
    <material name="light_gray">
  <color rgba="0.7 0.7 0.7 1"/>
</material>
   </visual>
   <collision>
    <origin xyz="0 0 -0.15"/>
    <geometry>
      <box size="0.03 0.05 0.15"/>
    </geometry>
  </collision>
<inertial>
    <origin xyz="0 0 0"/>
    <mass value="0.2"/>
    <inertia ixx="0.0001" iyy="0.0001" izz="0.0001"
             ixy="0" ixz="0" iyz="0"/>
</inertial> 
  </link>
<!-- FRONT LEFT THIGH -->
  <link name="fl_thigh">
   <visual>
     <origin xyz="0 0 -0.075"/> 
     <geometry>
        <box size="0.05 0.05 0.15"/>
     </geometry>
     <material name="light_gray">
  <color rgba="0.7 0.7 0.7 1"/>
</material>
   </visual>
   <collision>
    <origin xyz="0 0 -0.075"/>
    <geometry>
      <box size="0.05 0.05 0.15"/>
      </geometry>
    </collision>
    <inertial>
      <origin xyz="0 0 0"/>
      <mass value="0.2"/>                       <!-- tweak as you like -->
      <inertia ixx="0.0001" iyy="0.0001" izz="0.0001"
        ixy="0" ixz="0" iyz="0"/>
    </inertial>
  </link>
<!--FRONT LEFT SHIN -->
  <link name="fl_shin"> 
    <visual>
     <origin xyz="0 0 -0.15"/>
    <geometry>
      <box size="0.03 0.05 0.15"/>
    </geometry>
    <material name="light_gray">
  <color rgba="0.7 0.7 0.7 1"/>
</material>
   </visual>
   <collision>
    <origin xyz="0 0 -0.15"/>
    <geometry>
      <box size="0.03 0.05 0.15"/>
    </geometry>
   </collision>
   <inertial>
    <origin xyz="0 0 0"/>
    <mass value="0.2"/>
    <inertia ixx="0.0001" iyy="0.0001" izz="0.0001"
             ixy="0" ixz="0" iyz="0"/>
   </inertial> 
  </link>
<!-- HIND RIGHT THIGH -->
  <link name="hr_thigh">
   <visual>
     <origin xyz="0 0 -0.075"/> 
     <geometry>
        <box size="0.05 0.05 0.15"/>
     </geometry>
     <material name="dark_gray">
  <color rgba="0.4 0.4 0.4 1"/>
</material>
   </visual>
   <collision>
    <origin xyz="0 0 -0.075"/>
    <geometry>
      <box size="0.05 0.05 0.15"/>
    </geometry>
   </collision>
   <inertial>
    <origin xyz="0 0 0"/>
    <mass value="0.2"/>
    <inertia ixx="0.0001" iyy="0.0001" izz="0.0001"
             ixy="0" ixz="0" iyz="0"/>
   </inertial> 
  </link>
<!--HIND RIGHT SHIN -->
  <link name="hr_shin"> 
    <visual>
     <origin xyz="0 0 -0.15"/>
    <geometry>
      <box size="0.03 0.05 0.15"/>
    </geometry>
    <material name="dark_gray">
  <color rgba="0.4 0.4 0.4 1"/>
</material>
   </visual>
   <collision>
    <origin xyz="0 0 -0.15"/>
    <geometry>
      <box size="0.03 0.05 0.15"/>
    </geometry>
  </collision>
<inertial>
    <origin xyz="0 0 0"/>
    <mass value="0.2"/>
    <inertia ixx="0.0001" iyy="0.0001" izz="0.0001"
             ixy="0" ixz="0" iyz="0"/>
</inertial> 
  </link>
<!-- HIND LEFT THIGH -->
  <link name="hl_thigh">
   <visual>
     <origin xyz="0 0 -0.075"/> 
     <geometry>
        <box size="0.05 0.05 0.15"/>
     </geometry>
     <material name="dark_gray">
  <color rgba="0.4 0.4 0.4 1"/>
</material>
   </visual>
   <collision>
    <origin xyz="0 0 -0.075"/>
    <geometry>
      <box size="0.03 0.05 0.15"/>
    </geometry>
  </collision>
<inertial>
    <origin xyz="0 0 0"/>
    <mass value="0.2"/>
    <inertia ixx="0.0001" iyy="0.0001" izz="0.0001"
             ixy="0" ixz="0" iyz="0"/>
</inertial> 
  </link>
<!--HIND LEFT SHIN -->
  <link name="hl_shin"> 
    <visual>
     <origin xyz="0 0 -0.15"/>
    <geometry>
      <box size="0.03 0.05 0.15"/>
    </geometry>
    <material name="dark_gray">
  <color rgba="0.4 0.4 0.4 1"/>
</material>
   </visual>
   <collision>
    <origin xyz="0 0 -0.15"/>
    <geometry>
      <box size="0.05 0.05 0.15"/>
    </geometry>
  </collision>
<inertial>
    <origin xyz="0 0 0"/>
    <mass value="0.2"/>
    <inertia ixx="0.0001" iyy="0.0001" izz="0.0001"
             ixy="0" ixz="0" iyz="0"/>
</inertial> 
  </link>
<!-- FR HIP JOINT: torso → fr_thigh -->
  <joint name="fr_hip" type="revolute">
    <parent link="torso"/>
    <child link="fr_thigh"/>
    <origin xyz="0.1 -0.075 0" rpy="0 0 0"/> 
    <axis xyz="0 1 0"/> 
    <limit lower="-1.57" upper="1.57" effort="10" velocity="5"/>
  </joint>
<!-- FR KNEE JOINT: fr_thigh → fr_shin -->
  <joint name="fr_knee" type="revolute">
    <parent link="fr_thigh"/>
    <child link="fr_shin"/>
    <origin xyz="0 0 -0.075" rpy="0 0 0"/> 
    <axis xyz="0 1 0"/> <!-- same axis; you can flip this to reverse bend -->
    <limit lower="-1.57" upper="1.57" effort="10" velocity="5"/>
  </joint>
<!-- FL HIP JOINT: torso → fl_thigh -->
  <joint name="fl_hip" type="revolute">
    <parent link="torso"/>
    <child link="fl_thigh"/>
    <origin xyz="0.1 0.075 0" rpy="0 0 0"/> 
    <axis xyz="0 1 0"/> 
    <limit lower="-1.57" upper="1.57" effort="10" velocity="5"/>
  </joint>
<!-- FL KNEE JOINT: fr_thigh → fr_shin -->
  <joint name="fl_knee" type="revolute">
    <parent link="fl_thigh"/>
    <child link="fl_shin"/>
    <origin xyz="0 0 -0.075" rpy="0 0 0"/> 
    <axis xyz="0 1 0"/> <!-- same axis; you can flip this to reverse bend -->
    <limit lower="-1.57" upper="1.57" effort="10" velocity="5"/>
  </joint>
<!-- HR HIP JOINT: torso → hr_thigh -->
  <joint name="hr_hip" type="revolute">
    <parent link="torso"/>
    <child link="hr_thigh"/>
    <origin xyz="-0.1 -0.075 0" rpy="0 0 0"/> 
    <axis xyz="0 1 0"/> 
    <limit lower="-1.57" upper="1.57" effort="10" velocity="5"/>
  </joint>
<!-- HR KNEE JOINT: hr_thigh → hr_shin -->
  <joint name="hr_knee" type="revolute">
    <parent link="hr_thigh"/>
    <child link="hr_shin"/>
    <origin xyz="0 0 -0.075" rpy="0 0 0"/> 
    <axis xyz="0 1 0"/> <!-- same axis; you can flip this to reverse bend -->
    <limit lower="-1.57" upper="1.57" effort="10" velocity="5"/>
  </joint>
<!-- HL HIP JOINT: torso → hl_thigh -->
  <joint name="hl_hip" type="revolute">
    <parent link="torso"/>
    <child link="hl_thigh"/>
    <origin xyz="-0.1 0.075 0" rpy="0 0 0"/> 
    <axis xyz="0 1 0"/> 
    <limit lower="-1.57" upper="1.57" effort="10" velocity="5"/>
  </joint>
<!-- HL KNEE JOINT: hl_thigh → hl_shin -->
  <joint name="hl_knee" type="revolute">
    <parent link="hl_thigh"/>
    <child link="hl_shin"/>
    <origin xyz="0 0 -0.075" rpy="0 0 0"/> 
    <axis xyz="0 1 0"/> <!-- same axis; you can flip this to reverse bend -->
    <limit lower="-1.57" upper="1.57" effort="10" velocity="5"/>
  </joint>
</robot>